Traceback (most recent call last):
  File "/home/arbeit/Dokumente/GMPG/jupyterbook/env/lib/python3.8/site-packages/jupyter_cache/executors/utils.py", line 51, in single_nb_execution
    executenb(
  File "/home/arbeit/Dokumente/GMPG/jupyterbook/env/lib/python3.8/site-packages/nbclient/client.py", line 1082, in execute
    return NotebookClient(nb=nb, resources=resources, km=km, **kwargs).execute()
  File "/home/arbeit/Dokumente/GMPG/jupyterbook/env/lib/python3.8/site-packages/nbclient/util.py", line 74, in wrapped
    return just_run(coro(*args, **kwargs))
  File "/home/arbeit/Dokumente/GMPG/jupyterbook/env/lib/python3.8/site-packages/nbclient/util.py", line 53, in just_run
    return loop.run_until_complete(coro)
  File "/usr/lib/python3.8/asyncio/base_events.py", line 616, in run_until_complete
    return future.result()
  File "/home/arbeit/Dokumente/GMPG/jupyterbook/env/lib/python3.8/site-packages/nbclient/client.py", line 535, in async_execute
    await self.async_execute_cell(
  File "/home/arbeit/Dokumente/GMPG/jupyterbook/env/lib/python3.8/site-packages/nbclient/client.py", line 827, in async_execute_cell
    self._check_raise_for_error(cell, exec_reply)
  File "/home/arbeit/Dokumente/GMPG/jupyterbook/env/lib/python3.8/site-packages/nbclient/client.py", line 735, in _check_raise_for_error
    raise CellExecutionError.from_cell_and_msg(cell, exec_reply['content'])
nbclient.exceptions.CellExecutionError: An error occurred while executing the following cell:
------------------
import matplotlib.pyplot as plt
import numpy as np

t = np.arange(0.0, 2.0, 0.01)
s = 1 + np.sin(2*np.pi*t)
plt.plot(t, s)

plt.xlabel('time (s)')
plt.ylabel('voltage (mV)')
plt.title('Simple plot')
plt.grid(True)
plt.show()
------------------

[0;31m---------------------------------------------------------------------------[0m
[0;31mModuleNotFoundError[0m                       Traceback (most recent call last)
[0;32m<ipython-input-1-426a3c7245e2>[0m in [0;36m<module>[0;34m[0m
[0;32m----> 1[0;31m [0;32mimport[0m [0mmatplotlib[0m[0;34m.[0m[0mpyplot[0m [0;32mas[0m [0mplt[0m[0;34m[0m[0;34m[0m[0m
[0m[1;32m      2[0m [0;32mimport[0m [0mnumpy[0m [0;32mas[0m [0mnp[0m[0;34m[0m[0;34m[0m[0m
[1;32m      3[0m [0;34m[0m[0m
[1;32m      4[0m [0mt[0m [0;34m=[0m [0mnp[0m[0;34m.[0m[0marange[0m[0;34m([0m[0;36m0.0[0m[0;34m,[0m [0;36m2.0[0m[0;34m,[0m [0;36m0.01[0m[0;34m)[0m[0;34m[0m[0;34m[0m[0m
[1;32m      5[0m [0ms[0m [0;34m=[0m [0;36m1[0m [0;34m+[0m [0mnp[0m[0;34m.[0m[0msin[0m[0;34m([0m[0;36m2[0m[0;34m*[0m[0mnp[0m[0;34m.[0m[0mpi[0m[0;34m*[0m[0mt[0m[0;34m)[0m[0;34m[0m[0;34m[0m[0m

[0;31mModuleNotFoundError[0m: No module named 'matplotlib'
ModuleNotFoundError: No module named 'matplotlib'

