Traceback (most recent call last):
  File "/home/arbeit/Dokumente/GMPG/jupyterbook/env/lib/python3.8/site-packages/jupyter_cache/executors/utils.py", line 51, in single_nb_execution
    executenb(
  File "/home/arbeit/Dokumente/GMPG/jupyterbook/env/lib/python3.8/site-packages/nbclient/client.py", line 1082, in execute
    return NotebookClient(nb=nb, resources=resources, km=km, **kwargs).execute()
  File "/home/arbeit/Dokumente/GMPG/jupyterbook/env/lib/python3.8/site-packages/nbclient/util.py", line 74, in wrapped
    return just_run(coro(*args, **kwargs))
  File "/home/arbeit/Dokumente/GMPG/jupyterbook/env/lib/python3.8/site-packages/nbclient/util.py", line 53, in just_run
    return loop.run_until_complete(coro)
  File "/usr/lib/python3.8/asyncio/base_events.py", line 616, in run_until_complete
    return future.result()
  File "/home/arbeit/Dokumente/GMPG/jupyterbook/env/lib/python3.8/site-packages/nbclient/client.py", line 535, in async_execute
    await self.async_execute_cell(
  File "/home/arbeit/Dokumente/GMPG/jupyterbook/env/lib/python3.8/site-packages/nbclient/client.py", line 827, in async_execute_cell
    self._check_raise_for_error(cell, exec_reply)
  File "/home/arbeit/Dokumente/GMPG/jupyterbook/env/lib/python3.8/site-packages/nbclient/client.py", line 735, in _check_raise_for_error
    raise CellExecutionError.from_cell_and_msg(cell, exec_reply['content'])
nbclient.exceptions.CellExecutionError: An error occurred while executing the following cell:
------------------
dfT = pd.read_hdf('./data/df_tucholsky_meta.hd5')
------------------

[0;31m---------------------------------------------------------------------------[0m
[0;31mFileNotFoundError[0m                         Traceback (most recent call last)
[0;32m<ipython-input-2-cde01fc63bf2>[0m in [0;36m<module>[0;34m[0m
[0;32m----> 1[0;31m [0mdfT[0m [0;34m=[0m [0mpd[0m[0;34m.[0m[0mread_hdf[0m[0;34m([0m[0;34m'./data/df_tucholsky_meta.hd5'[0m[0;34m)[0m[0;34m[0m[0;34m[0m[0m
[0m
[0;32m~/Dokumente/GMPG/jupyterbook/env/lib/python3.8/site-packages/pandas/io/pytables.py[0m in [0;36mread_hdf[0;34m(path_or_buf, key, mode, errors, where, start, stop, columns, iterator, chunksize, **kwargs)[0m
[1;32m    385[0m [0;34m[0m[0m
[1;32m    386[0m         [0;32mif[0m [0;32mnot[0m [0mexists[0m[0;34m:[0m[0;34m[0m[0;34m[0m[0m
[0;32m--> 387[0;31m             [0;32mraise[0m [0mFileNotFoundError[0m[0;34m([0m[0;34mf"File {path_or_buf} does not exist"[0m[0;34m)[0m[0;34m[0m[0;34m[0m[0m
[0m[1;32m    388[0m [0;34m[0m[0m
[1;32m    389[0m         [0mstore[0m [0;34m=[0m [0mHDFStore[0m[0;34m([0m[0mpath_or_buf[0m[0;34m,[0m [0mmode[0m[0;34m=[0m[0mmode[0m[0;34m,[0m [0merrors[0m[0;34m=[0m[0merrors[0m[0;34m,[0m [0;34m**[0m[0mkwargs[0m[0;34m)[0m[0;34m[0m[0;34m[0m[0m

[0;31mFileNotFoundError[0m: File ./data/df_tucholsky_meta.hd5 does not exist
FileNotFoundError: File ./data/df_tucholsky_meta.hd5 does not exist

